Workbook

Sheet Unscaled Experiments
A1: Coverage in clustering experiments
B3: Automatic table based on "Experiments" | C3: Batch1 | I3: Batch2 | T3: Read me
B4: DLS dimension | C4: {=Experiments!C1:Q1} -> BHN_FWB | D4: BHN_FWB_AllExt | E4: Few_indicators_closest_DLS_coverage | F4: Few_indicators_SPI_preferred | G4: No_non_DLS | H4: Only_%_of_pop | I4: Few_indicators_closest_DLS_coverage_90 | J4: Few_indicators_SPI_preferred_90 | K4: Few_indicators_closeDLS_subPrimSchool | L4: No_non_DLS_90 | M4: Few_Indicators_subWatSani | N4: Only_OPP | O4: Baseline | P4: No_nonDLS_limExt | Q4: BHN | T4: Sheet "Experiment descriptions" holds an overview of the different experiemnts. The table to the left should not be touched, but comments to experiments can be written in the blue table below. Sheet "Experiments" is where the exact indicators going into the experiments can be found. New experiments can be created by adding a new column with 0s and 1s denoting which indicators should be included. Sheet "Overview of indicators and DLS" shows my evaluation of our indicators' relation to DLS.
B5: {=_xlfn.UNIQUE('Overview of indicators and DLS'!C4:C67)} -> Food & Nutrition | C5: {=SUMPRODUCT(('Overview of indicators and DLS'!$C$4:$C$66=$B5)*(Experiments!C$2:C$64=1))} -> 3 | D5: {=SUMPRODUCT(('Overview of indicators and DLS'!$C$4:$C$66=$B5)*(Experiments!D$2:D$64=1))} -> 5 | E5: {=SUMPRODUCT(('Overview of indicators and DLS'!$C$4:$C$66=$B5)*(Experiments!E$2:E$64=1))} -> 1 | F5: {=SUMPRODUCT(('Overview of indicators and DLS'!$C$4:$C$66=$B5)*(Experiments!F$2:F$64=1))} -> 1 | G5: {=SUMPRODUCT(('Overview of indicators and DLS'!$C$4:$C$66=$B5)*(Experiments!G$2:G$64=1))} -> 5 | H5: {=SUMPRODUCT(('Overview of indicators and DLS'!$C$4:$C$66=$B5)*(Experiments!H$2:H$64=1))} -> 2 | I5: {=SUMPRODUCT(('Overview of indicators and DLS'!$C$4:$C$66=$B5)*(Experiments!I$2:I$64=1))} -> 1 | J5: {=SUMPRODUCT(('Overview of indicators and DLS'!$C$4:$C$66=$B5)*(Experiments!J$2:J$64=1))} -> 1 | ... Q5: {=SUMPRODUCT(('Overview of indicators and DLS'!$C$4:$C$66=$B5)*(Experiments!Q$2:Q$64=1))} -> 3
B6: Health Care | C6: {=SUMPRODUCT(('Overview of indicators and DLS'!$C$4:$C$66=$B6)*(Experiments!C$2:C$64=1))} -> 7 | D6: {=SUMPRODUCT(('Overview of indicators and DLS'!$C$4:$C$66=$B6)*(Experiments!D$2:D$64=1))} -> 10 | E6: {=SUMPRODUCT(('Overview of indicators and DLS'!$C$4:$C$66=$B6)*(Experiments!E$2:E$64=1))} -> 1 | F6: {=SUMPRODUCT(('Overview of indicators and DLS'!$C$4:$C$66=$B6)*(Experiments!F$2:F$64=1))} -> 1 | G6: {=SUMPRODUCT(('Overview of indicators and DLS'!$C$4:$C$66=$B6)*(Experiments!G$2:G$64=1))} -> 10 | H6: {=SUMPRODUCT(('Overview of indicators and DLS'!$C$4:$C$66=$B6)*(Experiments!H$2:H$64=1))} -> 1 | I6: {=SUMPRODUCT(('Overview of indicators and DLS'!$C$4:$C$66=$B6)*(Experiments!I$2:I$64=1))} -> 1 | J6: {=SUMPRODUCT(('Overview of indicators and DLS'!$C$4:$C$66=$B6)*(Experiments!J$2:J$64=1))} -> 1 | ... Q6: {=SUMPRODUCT(('Overview of indicators and DLS'!$C$4:$C$66=$B6)*(Experiments!Q$2:Q$64=1))} -> 3
B7: Water | C7: {=SUMPRODUCT(('Overview of indicators and DLS'!$C$4:$C$66=$B7)*(Experiments!C$2:C$64=1))} -> 3 | D7: {=SUMPRODUCT(('Overview of indicators and DLS'!$C$4:$C$66=$B7)*(Experiments!D$2:D$64=1))} -> 4 | E7: {=SUMPRODUCT(('Overview of indicators and DLS'!$C$4:$C$66=$B7)*(Experiments!E$2:E$64=1))} -> 2 | F7: {=SUMPRODUCT(('Overview of indicators and DLS'!$C$4:$C$66=$B7)*(Experiments!F$2:F$64=1))} -> 2 | G7: {=SUMPRODUCT(('Overview of indicators and DLS'!$C$4:$C$66=$B7)*(Experiments!G$2:G$64=1))} -> 4 | H7: {=SUMPRODUCT(('Overview of indicators and DLS'!$C$4:$C$66=$B7)*(Experiments!H$2:H$64=1))} -> 1 | I7: {=SUMPRODUCT(('Overview of indicators and DLS'!$C$4:$C$66=$B7)*(Experiments!I$2:I$64=1))} -> 2 | J7: {=SUMPRODUCT(('Overview of indicators and DLS'!$C$4:$C$66=$B7)*(Experiments!J$2:J$64=1))} -> 2 | ... Q7: {=SUMPRODUCT(('Overview of indicators and DLS'!$C$4:$C$66=$B7)*(Experiments!Q$2:Q$64=1))} -> 3
B8: Sanitation | C8: {=SUMPRODUCT(('Overview of indicators and DLS'!$C$4:$C$66=$B8)*(Experiments!C$2:C$64=1))} -> 1 | D8: {=SUMPRODUCT(('Overview of indicators and DLS'!$C$4:$C$66=$B8)*(Experiments!D$2:D$64=1))} -> 2 | E8: {=SUMPRODUCT(('Overview of indicators and DLS'!$C$4:$C$66=$B8)*(Experiments!E$2:E$64=1))} -> 1 | F8: {=SUMPRODUCT(('Overview of indicators and DLS'!$C$4:$C$66=$B8)*(Experiments!F$2:F$64=1))} -> 1 | G8: {=SUMPRODUCT(('Overview of indicators and DLS'!$C$4:$C$66=$B8)*(Experiments!G$2:G$64=1))} -> 2 | H8: {=SUMPRODUCT(('Overview of indicators and DLS'!$C$4:$C$66=$B8)*(Experiments!H$2:H$64=1))} -> 1 | I8: {=SUMPRODUCT(('Overview of indicators and DLS'!$C$4:$C$66=$B8)*(Experiments!I$2:I$64=1))} -> 1 | J8: {=SUMPRODUCT(('Overview of indicators and DLS'!$C$4:$C$66=$B8)*(Experiments!J$2:J$64=1))} -> 1 | ... Q8: {=SUMPRODUCT(('Overview of indicators and DLS'!$C$4:$C$66=$B8)*(Experiments!Q$2:Q$64=1))} -> 1
B9: Food preparation | C9: {=SUMPRODUCT(('Overview of indicators and DLS'!$C$4:$C$66=$B9)*(Experiments!C$2:C$64=1))} -> 2 | D9: {=SUMPRODUCT(('Overview of indicators and DLS'!$C$4:$C$66=$B9)*(Experiments!D$2:D$64=1))} -> 2 | E9: {=SUMPRODUCT(('Overview of indicators and DLS'!$C$4:$C$66=$B9)*(Experiments!E$2:E$64=1))} -> 1 | F9: {=SUMPRODUCT(('Overview of indicators and DLS'!$C$4:$C$66=$B9)*(Experiments!F$2:F$64=1))} -> 1 | G9: {=SUMPRODUCT(('Overview of indicators and DLS'!$C$4:$C$66=$B9)*(Experiments!G$2:G$64=1))} -> 2 | H9: {=SUMPRODUCT(('Overview of indicators and DLS'!$C$4:$C$66=$B9)*(Experiments!H$2:H$64=1))} -> 1 | I9: {=SUMPRODUCT(('Overview of indicators and DLS'!$C$4:$C$66=$B9)*(Experiments!I$2:I$64=1))} -> 1 | J9: {=SUMPRODUCT(('Overview of indicators and DLS'!$C$4:$C$66=$B9)*(Experiments!J$2:J$64=1))} -> 1 | ... Q9: {=SUMPRODUCT(('Overview of indicators and DLS'!$C$4:$C$66=$B9)*(Experiments!Q$2:Q$64=1))} -> 0
B10: Thermal comfort | C10: {=SUMPRODUCT(('Overview of indicators and DLS'!$C$4:$C$66=$B10)*(Experiments!C$2:C$64=1))} -> 1 | D10: {=SUMPRODUCT(('Overview of indicators and DLS'!$C$4:$C$66=$B10)*(Experiments!D$2:D$64=1))} -> 1 | E10: {=SUMPRODUCT(('Overview of indicators and DLS'!$C$4:$C$66=$B10)*(Experiments!E$2:E$64=1))} -> 1 | F10: {=SUMPRODUCT(('Overview of indicators and DLS'!$C$4:$C$66=$B10)*(Experiments!F$2:F$64=1))} -> 1 | G10: {=SUMPRODUCT(('Overview of indicators and DLS'!$C$4:$C$66=$B10)*(Experiments!G$2:G$64=1))} -> 1 | H10: {=SUMPRODUCT(('Overview of indicators and DLS'!$C$4:$C$66=$B10)*(Experiments!H$2:H$64=1))} -> 1 | I10: {=SUMPRODUCT(('Overview of indicators and DLS'!$C$4:$C$66=$B10)*(Experiments!I$2:I$64=1))} -> 1 | J10: {=SUMPRODUCT(('Overview of indicators and DLS'!$C$4:$C$66=$B10)*(Experiments!J$2:J$64=1))} -> 1 | ... Q10: {=SUMPRODUCT(('Overview of indicators and DLS'!$C$4:$C$66=$B10)*(Experiments!Q$2:Q$64=1))} -> 0
B11: Non material / Non-DLS | C11: {=SUMPRODUCT(('Overview of indicators and DLS'!$C$4:$C$66=$B11)*(Experiments!C$2:C$64=1))} -> 9 | D11: {=SUMPRODUCT(('Overview of indicators and DLS'!$C$4:$C$66=$B11)*(Experiments!D$2:D$64=1))} -> 10 | E11: {=SUMPRODUCT(('Overview of indicators and DLS'!$C$4:$C$66=$B11)*(Experiments!E$2:E$64=1))} -> 0 | F11: {=SUMPRODUCT(('Overview of indicators and DLS'!$C$4:$C$66=$B11)*(Experiments!F$2:F$64=1))} -> 0 | G11: {=SUMPRODUCT(('Overview of indicators and DLS'!$C$4:$C$66=$B11)*(Experiments!G$2:G$64=1))} -> 0 | H11: {=SUMPRODUCT(('Overview of indicators and DLS'!$C$4:$C$66=$B11)*(Experiments!H$2:H$64=1))} -> 2 | I11: {=SUMPRODUCT(('Overview of indicators and DLS'!$C$4:$C$66=$B11)*(Experiments!I$2:I$64=1))} -> 0 | J11: {=SUMPRODUCT(('Overview of indicators and DLS'!$C$4:$C$66=$B11)*(Experiments!J$2:J$64=1))} -> 0 | ... Q11: {=SUMPRODUCT(('Overview of indicators and DLS'!$C$4:$C$66=$B11)*(Experiments!Q$2:Q$64=1))} -> 0
B12: Education | C12: {=SUMPRODUCT(('Overview of indicators and DLS'!$C$4:$C$66=$B12)*(Experiments!C$2:C$64=1))} -> 4 | D12: {=SUMPRODUCT(('Overview of indicators and DLS'!$C$4:$C$66=$B12)*(Experiments!D$2:D$64=1))} -> 5 | E12: {=SUMPRODUCT(('Overview of indicators and DLS'!$C$4:$C$66=$B12)*(Experiments!E$2:E$64=1))} -> 1 | F12: {=SUMPRODUCT(('Overview of indicators and DLS'!$C$4:$C$66=$B12)*(Experiments!F$2:F$64=1))} -> 1 | G12: {=SUMPRODUCT(('Overview of indicators and DLS'!$C$4:$C$66=$B12)*(Experiments!G$2:G$64=1))} -> 9 | H12: {=SUMPRODUCT(('Overview of indicators and DLS'!$C$4:$C$66=$B12)*(Experiments!H$2:H$64=1))} -> 3 | I12: {=SUMPRODUCT(('Overview of indicators and DLS'!$C$4:$C$66=$B12)*(Experiments!I$2:I$64=1))} -> 1 | J12: {=SUMPRODUCT(('Overview of indicators and DLS'!$C$4:$C$66=$B12)*(Experiments!J$2:J$64=1))} -> 1 | ... Q12: {=SUMPRODUCT(('Overview of indicators and DLS'!$C$4:$C$66=$B12)*(Experiments!Q$2:Q$64=1))} -> 0
B13: Social connectedness | C13: {=SUMPRODUCT(('Overview of indicators and DLS'!$C$4:$C$66=$B13)*(Experiments!C$2:C$64=1))} -> 3 | D13: {=SUMPRODUCT(('Overview of indicators and DLS'!$C$4:$C$66=$B13)*(Experiments!D$2:D$64=1))} -> 3 | E13: {=SUMPRODUCT(('Overview of indicators and DLS'!$C$4:$C$66=$B13)*(Experiments!E$2:E$64=1))} -> 2 | F13: {=SUMPRODUCT(('Overview of indicators and DLS'!$C$4:$C$66=$B13)*(Experiments!F$2:F$64=1))} -> 2 | G13: {=SUMPRODUCT(('Overview of indicators and DLS'!$C$4:$C$66=$B13)*(Experiments!G$2:G$64=1))} -> 3 | H13: {=SUMPRODUCT(('Overview of indicators and DLS'!$C$4:$C$66=$B13)*(Experiments!H$2:H$64=1))} -> 2 | I13: {=SUMPRODUCT(('Overview of indicators and DLS'!$C$4:$C$66=$B13)*(Experiments!I$2:I$64=1))} -> 2 | J13: {=SUMPRODUCT(('Overview of indicators and DLS'!$C$4:$C$66=$B13)*(Experiments!J$2:J$64=1))} -> 2 | ... Q13: {=SUMPRODUCT(('Overview of indicators and DLS'!$C$4:$C$66=$B13)*(Experiments!Q$2:Q$64=1))} -> 0
B14: Housing | C14: {=SUMPRODUCT(('Overview of indicators and DLS'!$C$4:$C$66=$B14)*(Experiments!C$2:C$64=1))} -> 0 | D14: {=SUMPRODUCT(('Overview of indicators and DLS'!$C$4:$C$66=$B14)*(Experiments!D$2:D$64=1))} -> 1 | E14: {=SUMPRODUCT(('Overview of indicators and DLS'!$C$4:$C$66=$B14)*(Experiments!E$2:E$64=1))} -> 1 | F14: {=SUMPRODUCT(('Overview of indicators and DLS'!$C$4:$C$66=$B14)*(Experiments!F$2:F$64=1))} -> 1 | G14: {=SUMPRODUCT(('Overview of indicators and DLS'!$C$4:$C$66=$B14)*(Experiments!G$2:G$64=1))} -> 1 | H14: {=SUMPRODUCT(('Overview of indicators and DLS'!$C$4:$C$66=$B14)*(Experiments!H$2:H$64=1))} -> 1 | I14: {=SUMPRODUCT(('Overview of indicators and DLS'!$C$4:$C$66=$B14)*(Experiments!I$2:I$64=1))} -> 1 | J14: {=SUMPRODUCT(('Overview of indicators and DLS'!$C$4:$C$66=$B14)*(Experiments!J$2:J$64=1))} -> 1 | ... Q14: {=SUMPRODUCT(('Overview of indicators and DLS'!$C$4:$C$66=$B14)*(Experiments!Q$2:Q$64=1))} -> 0
B15: Physical Connectedness | C15: {=SUMPRODUCT(('Overview of indicators and DLS'!$C$4:$C$66=$B15)*(Experiments!C$2:C$64=1))} -> 0 | D15: {=SUMPRODUCT(('Overview of indicators and DLS'!$C$4:$C$66=$B15)*(Experiments!D$2:D$64=1))} -> 0 | E15: {=SUMPRODUCT(('Overview of indicators and DLS'!$C$4:$C$66=$B15)*(Experiments!E$2:E$64=1))} -> 0 | F15: {=SUMPRODUCT(('Overview of indicators and DLS'!$C$4:$C$66=$B15)*(Experiments!F$2:F$64=1))} -> 0 | G15: {=SUMPRODUCT(('Overview of indicators and DLS'!$C$4:$C$66=$B15)*(Experiments!G$2:G$64=1))} -> 0 | H15: {=SUMPRODUCT(('Overview of indicators and DLS'!$C$4:$C$66=$B15)*(Experiments!H$2:H$64=1))} -> 0 | I15: {=SUMPRODUCT(('Overview of indicators and DLS'!$C$4:$C$66=$B15)*(Experiments!I$2:I$64=1))} -> 0 | J15: {=SUMPRODUCT(('Overview of indicators and DLS'!$C$4:$C$66=$B15)*(Experiments!J$2:J$64=1))} -> 0 | ... Q15: {=SUMPRODUCT(('Overview of indicators and DLS'!$C$4:$C$66=$B15)*(Experiments!Q$2:Q$64=1))} -> 0 | R15: Physical connectedness (mobility) is not well represented globally through time
B17: Number of indicators | C17: =SUM(C5:C15) -> 33 | D17: =SUM(D5:D15) -> 43 | E17: =SUM(E5:E15) -> 11 | F17: =SUM(F5:F15) -> 11 | G17: =SUM(G5:G15) -> 37 | H17: =SUM(H5:H15) -> 15 | I17: =SUM(I5:I15) -> 11 | J17: =SUM(J5:J15) -> 11 | ... Q17: =SUM(Q5:Q15) -> 10
B18: Of which SPI | C18: =SUM(Experiments!C2:C53) -> 33 | D18: =SUM(Experiments!D2:D53) -> 33 | E18: =SUM(Experiments!E2:E53) -> 7 | F18: =SUM(Experiments!F2:F53) -> 10 | G18: =SUM(Experiments!G2:G53) -> 28 | H18: =SUM(Experiments!H2:H53) -> 11 | I18: =SUM(Experiments!I2:I53) -> 7 | J18: =SUM(Experiments!J2:J53) -> 10 | ... Q18: =SUM(Experiments!Q2:Q53) -> 10
B19: Of which Extended | C19: =SUM(Experiments!C54:C64) -> 0 | D19: =SUM(Experiments!D54:D64) -> 10 | E19: =SUM(Experiments!E54:E64) -> 4 | F19: =SUM(Experiments!F54:F64) -> 1 | G19: =SUM(Experiments!G54:G64) -> 9 | H19: =SUM(Experiments!H54:H64) -> 4 | I19: =SUM(Experiments!I54:I64) -> 4 | J19: =SUM(Experiments!J54:J64) -> 1 | ... Q19: =SUM(Experiments!Q54:Q64) -> 0
A21: Batch | B21: Thoughts | C21: Before run | I21: After run | Q21: Results | AR21: % missing values in selected extended indicators
A22: 1 | B22: {=TRANSPOSE(_xlfn.ANCHORARRAY(C4))} -> BHN_FWB | C22: Only BHN and FWB from SPI to cluster the countries. Low amount of missingness high stability of clusters is expected between imputed sets. Housing dimension is lacking | Q22: #VALUE! | AB22: #VALUE! | AR22: #VALUE!
A23: 1 | B23: BHN_FWB_AllExt | C23: Only BHN, FWB and all extended variables to cluster the countries. Higher amount of missingness may cause unstable clusters. All possible DLS dimensions are covered.
A24: 1 | B24: Few_indicators_closest_DLS_coverage | C24: Choosing as few indicators as possible to cover DLS dimensions. Indicators are chosen so that they align most with the indicators presented in the subnational study. Redundancy is avoided. High missingness may cause problems
A25: 1 | B25: Few_indicators_SPI_preferred | C25: Choosing as few indicators as possible to cover DLS dimensions. Indicators are chosen from SPI if possiblle to avoid missing data porblems. Redundancy is avoided.
A26: 1 | B26: No_non_DLS | C26: Clustering where all variables that are not directly related to DLS dimensions are excluded, but all others are included | Q26: #VALUE!
A27: 1 | B27: Only_%_of_pop | C27: Clustering that only includes indicators that describes attainment as a proportion of population. This will provide clusters where we can easily determine national DLS coverage afterwards.
A28: 2 | B28: Few_indicators_closest_DLS_coverage_90 | C28: Similar to previous test with the same name, but this time the PCA should include 90% of the information | AB28: #VALUE!
A29: 2 | B29: Few_indicators_SPI_preferred_90 | C29: Similar to previous test with the same name, but this time the PCA should include 90% of the information
A30: 3 | B30: Few_indicators_closeDLS_subPrimSchool | C30: Primary school enrollment (Ext) is substituted by mean years of schooling (SPI) to reduce the missingness going into the clusters | Q30: #VALUE!
A31: 3 | B31: No_non_DLS_90 | C31: Similar to previous test with the same name, but this time the PCA should include 90% of the information
A32: 3 | B32: Few_Indicators_subWatSani | C32: Imputations for safely manged drinking water and sanitation (Ext), have a lot of uncertainty, in our countries of interest. This clustering substituses them, with the less strict indicators from SPI | AB32: #VALUE!
A33: 4 | B33: Only_OPP | C33: OPP reflects the quality of the institutions in a country, the resulting clusters should align with the colonial data.
B34: Baseline
B35: No_nonDLS_limExt | I35: Too many clusters
B36: BHN | C36: Clustering the whole world using BHN indicators led to too few clusters. Clustering only the countries present in the colonial data and the results are look promising
AB42: #VALUE!

Sheet Scaled Experiments
A1: These experiments were performed in a second round, where after imputation, the SPI indicators were scaled according to their scaling system. The new lag/lead imputation was used.
B3: Automatic table based on "Experiments" | T3: Read me
B4: DLS dimension | C4: {=Experiments!C1:S1} -> BHN_FWB | D4: BHN_FWB_AllExt | E4: Few_indicators_closest_DLS_coverage | F4: Few_indicators_SPI_preferred | G4: No_non_DLS | H4: Only_%_of_pop | I4: Few_indicators_closest_DLS_coverage_90 | J4: Few_indicators_SPI_preferred_90 | K4: Few_indicators_closeDLS_subPrimSchool | L4: No_non_DLS_90 | M4: Few_Indicators_subWatSani | N4: Only_OPP | O4: Baseline | P4: No_nonDLS_limExt | Q4: BHN | R4: No_non_DLS_BHNFWB | S4: All_indicators | T4: Sheet "Unscaled experiments/Scaled experiments" holds an overview of the different experiemnts. The table to the left should not be touched, but comments to experiments can be written in the blue table below. Sheet "Experiments" is where the exact indicators going into the experiments can be found. New experiments can be created by adding a new column with 0s and 1s denoting which indicators should be included. Sheet "Overview of indicators and DLS" shows my evaluation of our indicators' relation to DLS.
B5: {=_xlfn.UNIQUE('Overview of indicators and DLS'!C4:C67)} -> Food & Nutrition | C5: {=SUMPRODUCT(('Overview of indicators and DLS'!$C$4:$C$66=$B5)*(Experiments!C$2:C$64=1))} -> 3 | D5: {=SUMPRODUCT(('Overview of indicators and DLS'!$C$4:$C$66=$B5)*(Experiments!D$2:D$64=1))} -> 5 | E5: {=SUMPRODUCT(('Overview of indicators and DLS'!$C$4:$C$66=$B5)*(Experiments!E$2:E$64=1))} -> 1 | F5: {=SUMPRODUCT(('Overview of indicators and DLS'!$C$4:$C$66=$B5)*(Experiments!F$2:F$64=1))} -> 1 | G5: {=SUMPRODUCT(('Overview of indicators and DLS'!$C$4:$C$66=$B5)*(Experiments!G$2:G$64=1))} -> 5 | H5: {=SUMPRODUCT(('Overview of indicators and DLS'!$C$4:$C$66=$B5)*(Experiments!H$2:H$64=1))} -> 2 | I5: {=SUMPRODUCT(('Overview of indicators and DLS'!$C$4:$C$66=$B5)*(Experiments!I$2:I$64=1))} -> 1 | J5: {=SUMPRODUCT(('Overview of indicators and DLS'!$C$4:$C$66=$B5)*(Experiments!J$2:J$64=1))} -> 1 | ... S5: {=SUMPRODUCT(('Overview of indicators and DLS'!$C$4:$C$66=$B5)*(Experiments!S$2:S$64=1))} -> 5
B6: Health Care | C6: {=SUMPRODUCT(('Overview of indicators and DLS'!$C$4:$C$66=$B6)*(Experiments!C$2:C$64=1))} -> 7 | D6: {=SUMPRODUCT(('Overview of indicators and DLS'!$C$4:$C$66=$B6)*(Experiments!D$2:D$64=1))} -> 10 | E6: {=SUMPRODUCT(('Overview of indicators and DLS'!$C$4:$C$66=$B6)*(Experiments!E$2:E$64=1))} -> 1 | F6: {=SUMPRODUCT(('Overview of indicators and DLS'!$C$4:$C$66=$B6)*(Experiments!F$2:F$64=1))} -> 1 | G6: {=SUMPRODUCT(('Overview of indicators and DLS'!$C$4:$C$66=$B6)*(Experiments!G$2:G$64=1))} -> 10 | H6: {=SUMPRODUCT(('Overview of indicators and DLS'!$C$4:$C$66=$B6)*(Experiments!H$2:H$64=1))} -> 1 | I6: {=SUMPRODUCT(('Overview of indicators and DLS'!$C$4:$C$66=$B6)*(Experiments!I$2:I$64=1))} -> 1 | J6: {=SUMPRODUCT(('Overview of indicators and DLS'!$C$4:$C$66=$B6)*(Experiments!J$2:J$64=1))} -> 1 | ... S6: {=SUMPRODUCT(('Overview of indicators and DLS'!$C$4:$C$66=$B6)*(Experiments!S$2:S$64=1))} -> 10
B7: Water | C7: {=SUMPRODUCT(('Overview of indicators and DLS'!$C$4:$C$66=$B7)*(Experiments!C$2:C$64=1))} -> 3 | D7: {=SUMPRODUCT(('Overview of indicators and DLS'!$C$4:$C$66=$B7)*(Experiments!D$2:D$64=1))} -> 4 | E7: {=SUMPRODUCT(('Overview of indicators and DLS'!$C$4:$C$66=$B7)*(Experiments!E$2:E$64=1))} -> 2 | F7: {=SUMPRODUCT(('Overview of indicators and DLS'!$C$4:$C$66=$B7)*(Experiments!F$2:F$64=1))} -> 2 | G7: {=SUMPRODUCT(('Overview of indicators and DLS'!$C$4:$C$66=$B7)*(Experiments!G$2:G$64=1))} -> 4 | H7: {=SUMPRODUCT(('Overview of indicators and DLS'!$C$4:$C$66=$B7)*(Experiments!H$2:H$64=1))} -> 1 | I7: {=SUMPRODUCT(('Overview of indicators and DLS'!$C$4:$C$66=$B7)*(Experiments!I$2:I$64=1))} -> 2 | J7: {=SUMPRODUCT(('Overview of indicators and DLS'!$C$4:$C$66=$B7)*(Experiments!J$2:J$64=1))} -> 2 | ... S7: {=SUMPRODUCT(('Overview of indicators and DLS'!$C$4:$C$66=$B7)*(Experiments!S$2:S$64=1))} -> 4
B8: Sanitation | C8: {=SUMPRODUCT(('Overview of indicators and DLS'!$C$4:$C$66=$B8)*(Experiments!C$2:C$64=1))} -> 1 | D8: {=SUMPRODUCT(('Overview of indicators and DLS'!$C$4:$C$66=$B8)*(Experiments!D$2:D$64=1))} -> 2 | E8: {=SUMPRODUCT(('Overview of indicators and DLS'!$C$4:$C$66=$B8)*(Experiments!E$2:E$64=1))} -> 1 | F8: {=SUMPRODUCT(('Overview of indicators and DLS'!$C$4:$C$66=$B8)*(Experiments!F$2:F$64=1))} -> 1 | G8: {=SUMPRODUCT(('Overview of indicators and DLS'!$C$4:$C$66=$B8)*(Experiments!G$2:G$64=1))} -> 2 | H8: {=SUMPRODUCT(('Overview of indicators and DLS'!$C$4:$C$66=$B8)*(Experiments!H$2:H$64=1))} -> 1 | I8: {=SUMPRODUCT(('Overview of indicators and DLS'!$C$4:$C$66=$B8)*(Experiments!I$2:I$64=1))} -> 1 | J8: {=SUMPRODUCT(('Overview of indicators and DLS'!$C$4:$C$66=$B8)*(Experiments!J$2:J$64=1))} -> 1 | ... S8: {=SUMPRODUCT(('Overview of indicators and DLS'!$C$4:$C$66=$B8)*(Experiments!S$2:S$64=1))} -> 2
B9: Food preparation | C9: {=SUMPRODUCT(('Overview of indicators and DLS'!$C$4:$C$66=$B9)*(Experiments!C$2:C$64=1))} -> 2 | D9: {=SUMPRODUCT(('Overview of indicators and DLS'!$C$4:$C$66=$B9)*(Experiments!D$2:D$64=1))} -> 2 | E9: {=SUMPRODUCT(('Overview of indicators and DLS'!$C$4:$C$66=$B9)*(Experiments!E$2:E$64=1))} -> 1 | F9: {=SUMPRODUCT(('Overview of indicators and DLS'!$C$4:$C$66=$B9)*(Experiments!F$2:F$64=1))} -> 1 | G9: {=SUMPRODUCT(('Overview of indicators and DLS'!$C$4:$C$66=$B9)*(Experiments!G$2:G$64=1))} -> 2 | H9: {=SUMPRODUCT(('Overview of indicators and DLS'!$C$4:$C$66=$B9)*(Experiments!H$2:H$64=1))} -> 1 | I9: {=SUMPRODUCT(('Overview of indicators and DLS'!$C$4:$C$66=$B9)*(Experiments!I$2:I$64=1))} -> 1 | J9: {=SUMPRODUCT(('Overview of indicators and DLS'!$C$4:$C$66=$B9)*(Experiments!J$2:J$64=1))} -> 1 | ... S9: {=SUMPRODUCT(('Overview of indicators and DLS'!$C$4:$C$66=$B9)*(Experiments!S$2:S$64=1))} -> 2
B10: Thermal comfort | C10: {=SUMPRODUCT(('Overview of indicators and DLS'!$C$4:$C$66=$B10)*(Experiments!C$2:C$64=1))} -> 1 | D10: {=SUMPRODUCT(('Overview of indicators and DLS'!$C$4:$C$66=$B10)*(Experiments!D$2:D$64=1))} -> 1 | E10: {=SUMPRODUCT(('Overview of indicators and DLS'!$C$4:$C$66=$B10)*(Experiments!E$2:E$64=1))} -> 1 | F10: {=SUMPRODUCT(('Overview of indicators and DLS'!$C$4:$C$66=$B10)*(Experiments!F$2:F$64=1))} -> 1 | G10: {=SUMPRODUCT(('Overview of indicators and DLS'!$C$4:$C$66=$B10)*(Experiments!G$2:G$64=1))} -> 1 | H10: {=SUMPRODUCT(('Overview of indicators and DLS'!$C$4:$C$66=$B10)*(Experiments!H$2:H$64=1))} -> 1 | I10: {=SUMPRODUCT(('Overview of indicators and DLS'!$C$4:$C$66=$B10)*(Experiments!I$2:I$64=1))} -> 1 | J10: {=SUMPRODUCT(('Overview of indicators and DLS'!$C$4:$C$66=$B10)*(Experiments!J$2:J$64=1))} -> 1 | ... S10: {=SUMPRODUCT(('Overview of indicators and DLS'!$C$4:$C$66=$B10)*(Experiments!S$2:S$64=1))} -> 1
B11: Non material / Non-DLS | C11: {=SUMPRODUCT(('Overview of indicators and DLS'!$C$4:$C$66=$B11)*(Experiments!C$2:C$64=1))} -> 9 | D11: {=SUMPRODUCT(('Overview of indicators and DLS'!$C$4:$C$66=$B11)*(Experiments!D$2:D$64=1))} -> 10 | E11: {=SUMPRODUCT(('Overview of indicators and DLS'!$C$4:$C$66=$B11)*(Experiments!E$2:E$64=1))} -> 0 | F11: {=SUMPRODUCT(('Overview of indicators and DLS'!$C$4:$C$66=$B11)*(Experiments!F$2:F$64=1))} -> 0 | G11: {=SUMPRODUCT(('Overview of indicators and DLS'!$C$4:$C$66=$B11)*(Experiments!G$2:G$64=1))} -> 0 | H11: {=SUMPRODUCT(('Overview of indicators and DLS'!$C$4:$C$66=$B11)*(Experiments!H$2:H$64=1))} -> 2 | I11: {=SUMPRODUCT(('Overview of indicators and DLS'!$C$4:$C$66=$B11)*(Experiments!I$2:I$64=1))} -> 0 | J11: {=SUMPRODUCT(('Overview of indicators and DLS'!$C$4:$C$66=$B11)*(Experiments!J$2:J$64=1))} -> 0 | ... S11: {=SUMPRODUCT(('Overview of indicators and DLS'!$C$4:$C$66=$B11)*(Experiments!S$2:S$64=1))} -> 25
B12: Education | C12: {=SUMPRODUCT(('Overview of indicators and DLS'!$C$4:$C$66=$B12)*(Experiments!C$2:C$64=1))} -> 4 | D12: {=SUMPRODUCT(('Overview of indicators and DLS'!$C$4:$C$66=$B12)*(Experiments!D$2:D$64=1))} -> 5 | E12: {=SUMPRODUCT(('Overview of indicators and DLS'!$C$4:$C$66=$B12)*(Experiments!E$2:E$64=1))} -> 1 | F12: {=SUMPRODUCT(('Overview of indicators and DLS'!$C$4:$C$66=$B12)*(Experiments!F$2:F$64=1))} -> 1 | G12: {=SUMPRODUCT(('Overview of indicators and DLS'!$C$4:$C$66=$B12)*(Experiments!G$2:G$64=1))} -> 9 | H12: {=SUMPRODUCT(('Overview of indicators and DLS'!$C$4:$C$66=$B12)*(Experiments!H$2:H$64=1))} -> 3 | I12: {=SUMPRODUCT(('Overview of indicators and DLS'!$C$4:$C$66=$B12)*(Experiments!I$2:I$64=1))} -> 1 | J12: {=SUMPRODUCT(('Overview of indicators and DLS'!$C$4:$C$66=$B12)*(Experiments!J$2:J$64=1))} -> 1 | ... S12: {=SUMPRODUCT(('Overview of indicators and DLS'!$C$4:$C$66=$B12)*(Experiments!S$2:S$64=1))} -> 9
B13: Social connectedness | C13: {=SUMPRODUCT(('Overview of indicators and DLS'!$C$4:$C$66=$B13)*(Experiments!C$2:C$64=1))} -> 3 | D13: {=SUMPRODUCT(('Overview of indicators and DLS'!$C$4:$C$66=$B13)*(Experiments!D$2:D$64=1))} -> 3 | E13: {=SUMPRODUCT(('Overview of indicators and DLS'!$C$4:$C$66=$B13)*(Experiments!E$2:E$64=1))} -> 2 | F13: {=SUMPRODUCT(('Overview of indicators and DLS'!$C$4:$C$66=$B13)*(Experiments!F$2:F$64=1))} -> 2 | G13: {=SUMPRODUCT(('Overview of indicators and DLS'!$C$4:$C$66=$B13)*(Experiments!G$2:G$64=1))} -> 3 | H13: {=SUMPRODUCT(('Overview of indicators and DLS'!$C$4:$C$66=$B13)*(Experiments!H$2:H$64=1))} -> 2 | I13: {=SUMPRODUCT(('Overview of indicators and DLS'!$C$4:$C$66=$B13)*(Experiments!I$2:I$64=1))} -> 2 | J13: {=SUMPRODUCT(('Overview of indicators and DLS'!$C$4:$C$66=$B13)*(Experiments!J$2:J$64=1))} -> 2 | ... S13: {=SUMPRODUCT(('Overview of indicators and DLS'!$C$4:$C$66=$B13)*(Experiments!S$2:S$64=1))} -> 3
B14: Housing | C14: {=SUMPRODUCT(('Overview of indicators and DLS'!$C$4:$C$66=$B14)*(Experiments!C$2:C$64=1))} -> 0 | D14: {=SUMPRODUCT(('Overview of indicators and DLS'!$C$4:$C$66=$B14)*(Experiments!D$2:D$64=1))} -> 1 | E14: {=SUMPRODUCT(('Overview of indicators and DLS'!$C$4:$C$66=$B14)*(Experiments!E$2:E$64=1))} -> 1 | F14: {=SUMPRODUCT(('Overview of indicators and DLS'!$C$4:$C$66=$B14)*(Experiments!F$2:F$64=1))} -> 1 | G14: {=SUMPRODUCT(('Overview of indicators and DLS'!$C$4:$C$66=$B14)*(Experiments!G$2:G$64=1))} -> 1 | H14: {=SUMPRODUCT(('Overview of indicators and DLS'!$C$4:$C$66=$B14)*(Experiments!H$2:H$64=1))} -> 1 | I14: {=SUMPRODUCT(('Overview of indicators and DLS'!$C$4:$C$66=$B14)*(Experiments!I$2:I$64=1))} -> 1 | J14: {=SUMPRODUCT(('Overview of indicators and DLS'!$C$4:$C$66=$B14)*(Experiments!J$2:J$64=1))} -> 1 | ... S14: {=SUMPRODUCT(('Overview of indicators and DLS'!$C$4:$C$66=$B14)*(Experiments!S$2:S$64=1))} -> 1
B15: Physical Connectedness | C15: {=SUMPRODUCT(('Overview of indicators and DLS'!$C$4:$C$66=$B15)*(Experiments!C$2:C$64=1))} -> 0 | D15: {=SUMPRODUCT(('Overview of indicators and DLS'!$C$4:$C$66=$B15)*(Experiments!D$2:D$64=1))} -> 0 | E15: {=SUMPRODUCT(('Overview of indicators and DLS'!$C$4:$C$66=$B15)*(Experiments!E$2:E$64=1))} -> 0 | F15: {=SUMPRODUCT(('Overview of indicators and DLS'!$C$4:$C$66=$B15)*(Experiments!F$2:F$64=1))} -> 0 | G15: {=SUMPRODUCT(('Overview of indicators and DLS'!$C$4:$C$66=$B15)*(Experiments!G$2:G$64=1))} -> 0 | H15: {=SUMPRODUCT(('Overview of indicators and DLS'!$C$4:$C$66=$B15)*(Experiments!H$2:H$64=1))} -> 0 | I15: {=SUMPRODUCT(('Overview of indicators and DLS'!$C$4:$C$66=$B15)*(Experiments!I$2:I$64=1))} -> 0 | J15: {=SUMPRODUCT(('Overview of indicators and DLS'!$C$4:$C$66=$B15)*(Experiments!J$2:J$64=1))} -> 0 | ... S15: {=SUMPRODUCT(('Overview of indicators and DLS'!$C$4:$C$66=$B15)*(Experiments!S$2:S$64=1))} -> 0 | U15: Physical connectedness (mobility) is not well represented globally through time
B17: Number of indicators | C17: =SUM(C5:C15) -> 33 | D17: =SUM(D5:D15) -> 43 | E17: =SUM(E5:E15) -> 11 | F17: =SUM(F5:F15) -> 11 | G17: =SUM(G5:G15) -> 37 | H17: =SUM(H5:H15) -> 15 | I17: =SUM(I5:I15) -> 11 | J17: =SUM(J5:J15) -> 11 | ... S17: =SUM(S5:S15) -> 62
B18: Of which SPI | C18: =SUM(Experiments!C2:C53) -> 33 | D18: =SUM(Experiments!D2:D53) -> 33 | E18: =SUM(Experiments!E2:E53) -> 7 | F18: =SUM(Experiments!F2:F53) -> 10 | G18: =SUM(Experiments!G2:G53) -> 28 | H18: =SUM(Experiments!H2:H53) -> 11 | I18: =SUM(Experiments!I2:I53) -> 7 | J18: =SUM(Experiments!J2:J53) -> 10 | ... S18: =SUM(Experiments!S2:S53) -> 52
B19: Of which Extended | C19: =SUM(Experiments!C54:C64) -> 0 | D19: =SUM(Experiments!D54:D64) -> 10 | E19: =SUM(Experiments!E54:E64) -> 4 | F19: =SUM(Experiments!F54:F64) -> 1 | G19: =SUM(Experiments!G54:G64) -> 9 | H19: =SUM(Experiments!H54:H64) -> 4 | I19: =SUM(Experiments!I54:I64) -> 4 | J19: =SUM(Experiments!J54:J64) -> 1 | ... S19: =SUM(Experiments!S54:S64) -> 10
A21: Batch | B21: Thoughts | C21: Before run | I21: After run | Q21: Results | AR21: % missing values in selected extended indicators
A22: 1 | B22: {=TRANSPOSE(_xlfn.ANCHORARRAY(C4))} -> BHN_FWB | C22: Only BHN and FWB from SPI to cluster the countries. Low amount of missingness high stability of clusters is expected between imputed sets. Housing dimension is lacking | Q22: #VALUE! | AB22: #VALUE! | AR22: #VALUE!
A23: 1 | B23: BHN_FWB_AllExt | C23: Only BHN, FWB and all extended variables to cluster the countries. Higher amount of missingness may cause unstable clusters. All possible DLS dimensions are covered.
A24: 1 | B24: Few_indicators_closest_DLS_coverage | C24: Choosing as few indicators as possible to cover DLS dimensions. Indicators are chosen so that they align most with the indicators presented in the subnational study. Redundancy is avoided. High missingness may cause problems
A25: 1 | B25: Few_indicators_SPI_preferred | C25: Choosing as few indicators as possible to cover DLS dimensions. Indicators are chosen from SPI if possiblle to avoid missing data porblems. Redundancy is avoided.
A26: 1 | B26: No_non_DLS | C26: Clustering where all variables that are not directly related to DLS dimensions are excluded, but all others are included
A27: 1 | B27: Only_%_of_pop | C27: Clustering that only includes indicators that describes attainment as a proportion of population. This will provide clusters where we can easily determine national DLS coverage afterwards.
A28: 2 | B28: Few_indicators_closest_DLS_coverage_90 | C28: Similar to previous test with the same name, but this time the PCA should include 90% of the information
A29: 2 | B29: Few_indicators_SPI_preferred_90 | C29: Similar to previous test with the same name, but this time the PCA should include 90% of the information
A30: 3 | B30: Few_indicators_closeDLS_subPrimSchool | C30: Primary school enrollment (Ext) is substituted by mean years of schooling (SPI) to reduce the missingness going into the clusters
A31: 3 | B31: No_non_DLS_90 | C31: Similar to previous test with the same name, but this time the PCA should include 90% of the information | I31: Excluded due to exteme variation in the clustering
A32: 3 | B32: Few_Indicators_subWatSani | C32: Imputations for safely manged drinking water and sanitation (Ext), have a lot of uncertainty, in our countries of interest. This clustering substituses them, with the less strict indicators from SPI
A33: 4 | B33: Only_OPP | C33: OPP reflects the quality of the institutions in a country, the resulting clusters should align with the colonial data.
B34: Baseline
B35: No_nonDLS_limExt | I35: Too many clusters
B36: BHN | C36: Clustering the whole world using BHN indicators led to too few clusters. Clustering only the countries present in the colonial data and the results are look promising
B37: No_non_DLS_BHNFWB
B38: All_indicators
AB42: #VALUE!

Sheet Experiments
A1: Available Indicator (1 indicates that the indicator is included) | B1: Related DLS dimension | C1: BHN_FWB | D1: BHN_FWB_AllExt | E1: Few_indicators_closest_DLS_coverage | F1: Few_indicators_SPI_preferred | G1: No_non_DLS | H1: Only_%_of_pop | I1: Few_indicators_closest_DLS_coverage_90 | J1: Few_indicators_SPI_preferred_90 | K1: Few_indicators_closeDLS_subPrimSchool | L1: No_non_DLS_90 | M1: Few_Indicators_subWatSani | N1: Only_OPP | O1: Baseline | P1: No_nonDLS_limExt | Q1: BHN | R1: No_non_DLS_BHNFWB | S1: All_indicators
A2: {=TRANSPOSE('[1]1990-2020 Time-series data'!$Y$2:$BX$2)} -> Child stunting (% of pop.) | B2: Food & Nutrition | C2: 1 | D2: 1 | E2: 0 | F2: 0 | G2: 1 | H2: 1 | I2: 0 | J2: 0 | K2: 0 | L2: 1 | M2: 0 | N2: 0 | O2: 1 | P2: 1 | Q2: 1 | R2: 1 | S2: 1
A3: Deaths from infectious diseases (deaths/100,000) | B3: Health Care | C3: 1 | D3: 1 | E3: 0 | F3: 0 | G3: 1 | H3: 0 | I3: 0 | J3: 0 | K3: 0 | L3: 1 | M3: 0 | N3: 0 | O3: 1 | P3: 1 | Q3: 1 | R3: 1 | S3: 1
A4: Maternal mortality (deaths/100,000 live births) | B4: Health Care | C4: 1 | D4: 1 | E4: 0 | F4: 0 | G4: 1 | H4: 0 | I4: 0 | J4: 0 | K4: 0 | L4: 1 | M4: 0 | N4: 0 | O4: 1 | P4: 1 | Q4: 1 | R4: 1 | S4: 1
A5: Nutritional deficiencies (% of pop.) | B5: Food & Nutrition | C5: 1 | D5: 1 | E5: 1 | F5: 1 | G5: 1 | H5: 1 | I5: 1 | J5: 1 | K5: 1 | L5: 1 | M5: 1 | N5: 0 | O5: 1 | P5: 1 | Q5: 1 | R5: 1 | S5: 1
A6: Diet low in fruits and vegetables (0=low risk; 100=high risk) | B6: Food & Nutrition | C6: 1 | D6: 1 | E6: 0 | F6: 0 | G6: 1 | H6: 0 | I6: 0 | J6: 0 | K6: 0 | L6: 1 | M6: 0 | N6: 0 | O6: 1 | P6: 1 | Q6: 1 | R6: 1 | S6: 1
A7: Child mortality (deaths/1,000 live births) | B7: Health Care | C7: 1 | D7: 1 | E7: 0 | F7: 0 | G7: 1 | H7: 0 | I7: 0 | J7: 0 | K7: 0 | L7: 1 | M7: 0 | N7: 0 | O7: 1 | P7: 1 | Q7: 1 | R7: 1 | S7: 1
A8: No access to a handwashing facility (0=low risk; 100=high risk) | B8: Water | C8: 1 | D8: 1 | E8: 1 | F8: 1 | G8: 1 | H8: 0 | I8: 1 | J8: 1 | K8: 1 | L8: 1 | M8: 1 | N8: 0 | O8: 1 | P8: 1 | Q8: 1 | R8: 1 | S8: 1
A9: Deaths from unsafe water, sanitation and hygiene (deaths/100,000) | B9: Water | C9: 1 | D9: 1 | E9: 0 | F9: 0 | G9: 1 | H9: 0 | I9: 0 | J9: 0 | K9: 0 | L9: 1 | M9: 0 | N9: 0 | O9: 1 | P9: 1 | Q9: 1 | R9: 1 | S9: 1
A10: Improved sanitation (proportion of pop.) | B10: Sanitation | C10: 1 | D10: 1 | E10: 0 | F10: 1 | G10: 1 | H10: 0 | I10: 0 | J10: 1 | K10: 0 | L10: 1 | M10: 1 | N10: 0 | O10: 1 | P10: 1 | Q10: 1 | R10: 1 | S10: 1
A11: Improved water source (proportion of pop.) | B11: Water | C11: 1 | D11: 1 | E11: 0 | F11: 1 | G11: 1 | H11: 0 | I11: 0 | J11: 1 | K11: 0 | L11: 1 | M11: 1 | N11: 0 | O11: 1 | P11: 1 | Q11: 1 | R11: 1 | S11: 1
A12: Deaths from household air pollution (deaths/100,000) | B12: Food preparation | C12: 1 | D12: 1 | E12: 0 | F12: 0 | G12: 1 | H12: 0 | I12: 0 | J12: 0 | K12: 0 | L12: 1 | M12: 0 | N12: 0 | O12: 1 | P12: 1 | Q12: 0 | R12: 1 | S12: 1
A13: Prevalence of cooking with coal/biomass (proportion of pop.) | B13: Food preparation | C13: 1 | D13: 1 | E13: 1 | F13: 1 | G13: 1 | H13: 1 | I13: 1 | J13: 1 | K13: 1 | L13: 1 | M13: 1 | N13: 0 | O13: 1 | P13: 1 | Q13: 0 | R13: 1 | S13: 1
A14: Access to electricity (% of pop.) | B14: Thermal comfort | C14: 1 | D14: 1 | E14: 1 | F14: 1 | G14: 1 | H14: 1 | I14: 1 | J14: 1 | K14: 1 | L14: 1 | M14: 1 | N14: 0 | O14: 1 | P14: 1 | Q14: 0 | R14: 1 | S14: 1
... A64: Intentional homicide victims | B64: Non material / Non-DLS | C64: 0 | D64: 1 | E64: 0 | F64: 0 | G64: 0 | H64: 0 | I64: 0 | J64: 0 | K64: 0 | L64: 0 | M64: 0 | N64: 0 | O64: 0 | P64: 0 | Q64: 0 | R64: 0 | S64: 1
B65: Physical Connectedness

Sheet Overview of indicators and DLS
A3: SPI | B3: Available indicators | C3: Related DLS dimension
A4: BHN | B4: {=TRANSPOSE('[1]1990-2020 Time-series data'!$Y$2:$BX$2)} -> Child stunting (% of pop.) | C4: Food & Nutrition
B5: Deaths from infectious diseases (deaths/100,000) | C5: Health Care
B6: Maternal mortality (deaths/100,000 live births) | C6: Health Care
B7: Nutritional deficiencies (% of pop.) | C7: Food & Nutrition
B8: Diet low in fruits and vegetables (0=low risk; 100=high risk) | C8: Food & Nutrition
B9: Child mortality (deaths/1,000 live births) | C9: Health Care
B10: No access to a handwashing facility (0=low risk; 100=high risk) | C10: Water
B11: Deaths from unsafe water, sanitation and hygiene (deaths/100,000) | C11: Water
B12: Improved sanitation (proportion of pop.) | C12: Sanitation
B13: Improved water source (proportion of pop.) | C13: Water
A14: FWB | B14: Deaths from household air pollution (deaths/100,000) | C14: Food preparation
B15: Prevalence of cooking with coal/biomass (proportion of pop.) | C15: Food preparation
B16: Access to electricity (% of pop.) | C16: Thermal comfort
B17: Deaths from road injuries (deaths/100,000) | C17: Non material / Non-DLS
B18: Political violence (0=no violence; 4=violence often) | C18: Non material / Non-DLS
B19: Political killings and torture (0=low freedom; 1=high freedom) | C19: Non material / Non-DLS
B20: Intimate partner violence against women (% of women aged 15+) | C20: Non material / Non-DLS
B21: Interpersonal violence (deaths/100,000) | C21: Non material / Non-DLS
B22: Population with no education (proportion of pop.) | C22: Education
B23: Gender parity in basic education (distance from parity) | C23: Education
B24: Equal access to quality education (0=unequal; 4=equal) | C24: Education
B25: Mean years of schooling (years) | C25: Education
B26: Alternative sources of information (0=low; 1=high) | C26: Social connectedness
... B36: Species protection (0=low; 100=high) | C36: Non material / Non-DLS
A37: OPP | B37: Freedom of religion (0=no freedom; 4=full freedom) | C37: Non material / Non-DLS
B38: Property rights for women (0=no rights; 5=full rights) | C38: Non material / Non-DLS
B39: Freedom of assembly (0=no freedom; 4=full freedom) | C39: Non material / Non-DLS
B40: Access to justice (0=nonexistent; 1=observed) | C40: Non material / Non-DLS
B41: Freedom of discussion (0=low; 1=high) | C41: Non material / Non-DLS
B42: Political rights (1=full rights; 7=no rights) | C42: Non material / Non-DLS
B43: Public sector corruption (0=low corruption; 1=high corruption) | C43: Non material / Non-DLS
B44: Freedom of domestic movement (0=low; 1=high) | C44: Non material / Non-DLS
B45: Satisfied demand for contraception (% satisfied demand) | C45: Non material / Non-DLS
B46: Early marriage (% of married women aged 15-19) | C46: Non material / Non-DLS
B47: Vulnerable employment (% of total employment) | C47: Non material / Non-DLS
B48: Equal protection of social groups (0=low; 1=high) | C48: Non material / Non-DLS
B49: Equal access to power (0=low; 1=high) | C49: Non material / Non-DLS
... B55: Years of tertiary schooling (years) | C55: Education
A56: Extra sources | B56: Primary School Enrollment (% of pop in school age) | C56: Education
...

Sheet Sheet1
A1: DLS dimension | B1: Baseline | C1: BHN_FWB | D1: SPI_Extended | E1: DLS_dim_only | F1: DLS_dim_only_limExt | G1: DLS_dim_only_BHNFWB | H1: DLSFew_coverage | I1: DLSFew_coverage_90 | J1: DLSFew_bestAlignment | K1: DLSFew_bestAlignment_90
A2: Food & Nutrition | B2: 3 | C2: 3 | D2: 5 | E2: 5 | F2: 3 | G2: 5 | H2: 1 | I2: 1 | J2: 1 | K2: 1
A3: Health Care | B3: 7 | C3: 7 | D3: 10 | E3: 10 | F3: 7 | G3: 10 | H3: 1 | I3: 1 | J3: 1 | K3: 1
A4: Water | B4: 3 | C4: 3 | D4: 4 | E4: 4 | F4: 3 | G4: 4 | H4: 2 | I4: 2 | J4: 2 | K4: 2
A5: Sanitation | B5: 1 | C5: 1 | D5: 2 | E5: 2 | F5: 1 | G5: 2 | H5: 1 | I5: 1 | J5: 1 | K5: 1 | P5: {=TRANSPOSE(B1:K1)} -> Baseline
A6: Food preparation | B6: 2 | C6: 2 | D6: 2 | E6: 2 | F6: 2 | G6: 2 | H6: 1 | I6: 1 | J6: 1 | K6: 1 | P6: BHN_FWB
A7: Thermal comfort | B7: 1 | C7: 1 | D7: 1 | E7: 1 | F7: 1 | G7: 1 | H7: 1 | I7: 1 | J7: 1 | K7: 1 | P7: SPI_Extended
A8: Education | B8: 8 | C8: 4 | D8: 9 | E8: 9 | F8: 8 | G8: 5 | H8: 1 | I8: 1 | J8: 1 | K8: 1 | P8: DLS_dim_only
A9: Social connectedness | B9: 3 | C9: 3 | D9: 3 | E9: 3 | F9: 3 | G9: 3 | H9: 2 | I9: 2 | J9: 2 | K9: 2 | P9: DLS_dim_only_limExt
A10: Housing | B10: 0 | C10: 0 | D10: 1 | E10: 1 | F10: 1 | G10: 1 | H10: 1 | I10: 1 | J10: 1 | K10: 1 | P10: DLS_dim_only_BHNFWB
A11: Physical Connectedness | B11: 0 | C11: 0 | D11: 0 | E11: 0 | F11: 0 | G11: 0 | H11: 0 | I11: 0 | J11: 0 | K11: 0 | P11: DLSFew_coverage
A12: Non material / Non-DLS | B12: 24 | C12: 9 | D12: 25 | E12: 0 | F12: 0 | G12: 0 | H12: 0 | I12: 0 | J12: 0 | K12: 0 | P12: DLSFew_coverage_90
A13: Number of indicators | B13: 52 | C13: 33 | D13: 62 | E13: 37 | F13: 29 | G13: 33 | H13: 11 | I13: 11 | J13: 11 | K13: 11 | P13: DLSFew_bestAlignment
A14: Of which SPI | B14: 52 | C14: 33 | D14: 52 | E14: 28 | F14: 28 | G14: 24 | H14: 10 | I14: 10 | J14: 7 | K14: 7 | P14: DLSFew_bestAlignment_90
A15: Of which Extended | B15: 0 | C15: 0 | D15: 10 | E15: 9 | F15: 1 | G15: 9 | H15: 1 | I15: 1 | J15: 4 | K15: 4

Sheet New table in report
A1: # | B1: DLS Indicator | C1: DHS Variables with Minimum Thresholds Used to Define DLS | D1: Indicators used in this study | E1: Source | F1: DLS answered | G1: Link
A2: 1 | B2: Housing | C2: Floor Material (hv213): Finished floor material (parquet or polished wood, tiles, cement, carpet) Household size (hv009)/Number of rooms (hv216): Number of people per room is less than 3 | D2: Share of urban population living in slums | E2: UN HABITAT | F2: / | G2: https://data.unhabitat.org/pages/housing-slums-and-informal-settlements | H2: The indicator used is an aggregate indicator measuring lack of one or more of the following: access to improved water, improved sanitation, sufficient living area, housing durability and security of tenure. Rural population is not considered.
A3: 2 | B3: Thermal comfort | C3: Wall material (hv214): Finished wall materials (tin, cement, stone, bricks, wood planks) Roof material (hv215): Finished roof materials (tin, wood, ceramic tiles, cement, roofing shingles) Access to electricity (hv206): Binary indicator. If household has access, response = 1 | D3: Access to electricity | E3: SPI | F3: /
A4: 3 | B4: Food/Nutrition | C4: BMI (v445): If BMI is below 1850, then undernourished. Height (v438): For BMI calculation Weight (v437): For BMI calculation | D4: Child stunting | E4: SPI | F4: +
D5: Nutritional deficiencies | E5: SPI
D6: Diet low in fruits and vegetables | E6: SPI
D7: Daily Calorie supply | E7: FAO
D8: Protein supply | E8: FAO
A9: 4 | B9: Food prep/storage | C9: Household has a refrigerator (hv209): Binary indicator. If household has refrigerator, response = 1 Household uses modern cooking fuel (hv239): Household has access to at least one of the following types of fuels: gas, LPG, electricity, solar | D9: Deaths from household air pollution | E9: SPI | F9: /
D10: Prevalence of cooking with coal/biomass | E10: SPI
D11: Clean Fuels | E11: IEA | G11: https://data.worldbank.org/indicator/EG.CFT.ACCS.ZS
A12: 5 | B12: Water | C12: Main source of drinking water (hv201): Household has access to “Safely managed” drinking water as per WASH guidelines | D12: No access to a handwashing facility | E12: SPI | F12: +
D13: Deaths from unsafe water, sanitation and hygiene | E13: SPI
D14: Improved water source | E14: SPI
D15: Safely Managed Drinking Water | E15: WHO / UNICEF JMP | G15: https://data.worldbank.org/indicator/SH.H2O.SMDW.ZS
A16: 6 | B16: Sanitation | C16: Type of toilet (hv205): Household has access to “Safely managed” toilet facility as per WASH guidelines | D16: Improved sanitation | E16: SPI | F16: +
D17: Safely Managed Sanitation | E17: WHO / UNICEF JMP | G17: https://data.worldbank.org/indicator/SH.STA.SMSS.ZS
A18: 7 | B18: Provision of health care | C18: Problems faced in getting healthcare (v467a–v467j): Binary indicator. If any of v467a–v467j indicates no access, response = 1 | D18: Deaths from infectious diseases | E18: SPI | F18: +
D19: Maternal mortality | E19: SPI
D20: Child mortality | E20: SPI
D21: Life expectancy at 60 years | E21: SPI
D22: Healthy life expectancy | E22: WHO | G22: https://www.who.int/data/gho/data/indicators/indicator-details/GHO/gho-ghe-hale-healthy-life-expectancy-at-birth
D23: Premature deaths from non-communicable diseases | E23: SPI
D24: Equal access to quality healthcare | E24: SPI
D25: Universal health coverage | E25: SPI
D26: Physicians per 1000 | E26: World Bank | G26: https://databank.worldbank.org/source/health-nutrition-and-population-statistics/Series/SH.MED.PHYS.ZS
D27: Hospital beds per 1000 | E27: World Bank | G27: https://databank.worldbank.org/source/world-development-indicators/Series/SH.MED.BEDS.ZS
A28: 8 | B28: Education | C28: Is the household member still in school? (hv110): Binary indicator. If in school and belongs to compulsory schooling age, response = 1 Age of household members (hv105): Compulsory schooling age between 6 and 10 | D28: Primary School Enrollment | E28: UNESCO | F28: + | G28: https://data.worldbank.org/indicator/SE.PRM.NENR
D29: Gender parity in basic/advanced education (distance from parity) | E29: SPI
D30: Equal access to quality education (0=unequal; 4=equal) | E30: SPI
D31: Mean years of schooling (years) | E31: SPI
D32: Population with advanced education (proportion of pop.) | E32: SPI
D33: Years of tertiary schooling (years) | E33: SPI
D34: Respect for academic freedom (0=low; 1=high) | E34: SPI
D35: Population with no/advanced education (proportion of pop.) | E35: SPI
A36: 9 | B36: Social Connectedness | C36: Household possesses radio (hv207): If has radio, response = 1 Household possesses television (hv208): If has TV, response = 1 Household possesses computer (hv243): If has computer, response = 1 Household possesses telephone (hv221): If has telephone, response = 1 Household possesses cell phone (hv243A): If has cellphone, response = 1(All Binary Indicators) | D36: Alternative sources of information (0=low; 1=high) | E36: SPI | F36: +
D37: Internet users (% of pop.) | E37: SPI
D38: Mobile and landline telephone subscriptions (subscriptions/100 people) | E38: SPI
A39: 10 | B39: Physical Connectedness | C39: Household possesses bicycle (hv210): If has bicycle, response = 1 Household possesses motorcycle (hv211): If has motorcycle, response = 1 Household possesses car (hv212): If has car, response = 1(All Binary Indicators) | F39: -

Sheet Old table in report
A1: DLS dimensions | B1: DHS variables | C1: Indicator used in this study | D1: Source | E1: Comment
A2: Housing | B2: Floor type | C2: Share slums Share of urban population living in slums
B3: Household size
B4: Number of rooms
A5: Thermal comfort | B5: Wall type | C5: Access to electricity
B6: Roof type
B7: Electricity access
A8: Food & nutrition | B8: Age of household members | C8: Child stunting
B9: Weight/heigh of household members
C10: Nutritional deficiencies
C11: Diet low in fruits and vegetables
C12: Daily Calorie supply
C13: Protein supply
A14: Food preparation | B14: Use of modern cooking fuels | C14: Deaths from household air pollution
C15: Prevalence of cooking with coal/biomass
C16: Clean Fuels
B17: Possession of fridge
A18: Water | B18: Main water source (based on WASH criteria) | C18: No access to a handwashing facility
C19: Deaths from unsafe water, sanitation and hygiene
C20: Improved water source
C21: Safely Managed Drinking Water
A22: Sanitation | B22: Type of toilet (based on WASH criteria) | C22: Improved sanitation
C23: Safely Managed Sanitation
A24: Health Care | C24: Deaths from infectious diseases
C25: Maternal mortality
C26: Child mortality
C27: Life expectancy at 60 years
C28: Healthy life expectancy
C29: Premature deaths from non-communicable diseases
B30: Reason for not using health care related to accessibility issues | C30: Equal access to quality healthcare
C31: Universal health coverage
C32: Physicians per 1000
C33: Hospital beds per 1000
A34: Education | B34: Age of household members | C34: Primary School Enrollment
C35: Gender parity in basic/advanced education (distance from parity)
C36: Equal access to quality education (0=unequal; 4=equal)
B37: Highest level of schooling | C37: Mean years of schooling (years)
C38: Population with advanced education (proportion of pop.)
C39: Years of tertiary schooling (years)
C40: Respect for academic freedom (0=low; 1=high)
...
