Workbook

Sheet Experiment Descriptions
A1: Coverage in clustering experiments
B3: Automatic table based on "Experiments" | C3: First test run | R3: Read me
B4: DLS dimension | C4: {=Experiments!C1:P1} -> BHN_FWB | D4: BHN_FWB_AllExt | E4: Few_indicators_closest_DLS_coverage | F4: Few indicators_SPI_preferred | G4: No_non_DLS | H4: Only_%_of_pop | I4: Add new here | J4: 0 | K4: 0 | L4: 0 | M4: 0 | N4: 0 | O4: 0 | P4: 0 | R4: Sheet "Experiment descriptions" holds an overview of the different experiemnts. The table to the left should not be touched, but comments to experiments can be written in the blue table below. Sheet "Experiments" is where the exact indicators going into the experiments can be found. New experiments can be created by adding a new column with 0s and 1s denoting which indicators should be included. Sheet "Overview of indicators and DLS" shows my evaluation of our indicators' relation to DLS.
B5: {=_xlfn.UNIQUE('Overview of indicators and DLS'!C4:C67)} -> Food & Nutrition | C5: {=SUMPRODUCT(('Overview of indicators and DLS'!$C$4:$C$66=$B5)*(Experiments!C$2:C$64=1))} -> 3 | D5: {=SUMPRODUCT(('Overview of indicators and DLS'!$C$4:$C$66=$B5)*(Experiments!D$2:D$64=1))} -> 5 | E5: {=SUMPRODUCT(('Overview of indicators and DLS'!$C$4:$C$66=$B5)*(Experiments!E$2:E$64=1))} -> 1 | F5: {=SUMPRODUCT(('Overview of indicators and DLS'!$C$4:$C$66=$B5)*(Experiments!F$2:F$64=1))} -> 1 | G5: {=SUMPRODUCT(('Overview of indicators and DLS'!$C$4:$C$66=$B5)*(Experiments!G$2:G$64=1))} -> 5 | H5: {=SUMPRODUCT(('Overview of indicators and DLS'!$C$4:$C$66=$B5)*(Experiments!H$2:H$64=1))} -> 2 | I5: {=SUMPRODUCT(('Overview of indicators and DLS'!$C$4:$C$66=$B5)*(Experiments!J$2:J$64=1))} -> 0 | J5: {=SUMPRODUCT(('Overview of indicators and DLS'!$C$4:$C$66=$B5)*(Experiments!K$2:K$64=1))} -> 0 | K5: {=SUMPRODUCT(('Overview of indicators and DLS'!$C$4:$C$66=$B5)*(Experiments!L$2:L$64=1))} -> 0 | L5: {=SUMPRODUCT(('Overview of indicators and DLS'!$C$4:$C$66=$B5)*(Experiments!M$2:M$64=1))} -> 0 | M5: {=SUMPRODUCT(('Overview of indicators and DLS'!$C$4:$C$66=$B5)*(Experiments!N$2:N$64=1))} -> 0 | N5: {=SUMPRODUCT(('Overview of indicators and DLS'!$C$4:$C$66=$B5)*(Experiments!O$2:O$64=1))} -> 0 | O5: {=SUMPRODUCT(('Overview of indicators and DLS'!$C$4:$C$66=$B5)*(Experiments!P$2:P$64=1))} -> 0
B6: Health Care | C6: {=SUMPRODUCT(('Overview of indicators and DLS'!$C$4:$C$66=$B6)*(Experiments!C$2:C$64=1))} -> 7 | D6: {=SUMPRODUCT(('Overview of indicators and DLS'!$C$4:$C$66=$B6)*(Experiments!D$2:D$64=1))} -> 10 | E6: {=SUMPRODUCT(('Overview of indicators and DLS'!$C$4:$C$66=$B6)*(Experiments!E$2:E$64=1))} -> 1 | F6: {=SUMPRODUCT(('Overview of indicators and DLS'!$C$4:$C$66=$B6)*(Experiments!F$2:F$64=1))} -> 1 | G6: {=SUMPRODUCT(('Overview of indicators and DLS'!$C$4:$C$66=$B6)*(Experiments!G$2:G$64=1))} -> 10 | H6: {=SUMPRODUCT(('Overview of indicators and DLS'!$C$4:$C$66=$B6)*(Experiments!H$2:H$64=1))} -> 1 | I6: {=SUMPRODUCT(('Overview of indicators and DLS'!$C$4:$C$66=$B6)*(Experiments!J$2:J$64=1))} -> 0 | J6: {=SUMPRODUCT(('Overview of indicators and DLS'!$C$4:$C$66=$B6)*(Experiments!K$2:K$64=1))} -> 0 | K6: {=SUMPRODUCT(('Overview of indicators and DLS'!$C$4:$C$66=$B6)*(Experiments!L$2:L$64=1))} -> 0 | L6: {=SUMPRODUCT(('Overview of indicators and DLS'!$C$4:$C$66=$B6)*(Experiments!M$2:M$64=1))} -> 0 | M6: {=SUMPRODUCT(('Overview of indicators and DLS'!$C$4:$C$66=$B6)*(Experiments!N$2:N$64=1))} -> 0 | N6: {=SUMPRODUCT(('Overview of indicators and DLS'!$C$4:$C$66=$B6)*(Experiments!O$2:O$64=1))} -> 0 | O6: {=SUMPRODUCT(('Overview of indicators and DLS'!$C$4:$C$66=$B6)*(Experiments!P$2:P$64=1))} -> 0
B7: Water | C7: {=SUMPRODUCT(('Overview of indicators and DLS'!$C$4:$C$66=$B7)*(Experiments!C$2:C$64=1))} -> 3 | D7: {=SUMPRODUCT(('Overview of indicators and DLS'!$C$4:$C$66=$B7)*(Experiments!D$2:D$64=1))} -> 4 | E7: {=SUMPRODUCT(('Overview of indicators and DLS'!$C$4:$C$66=$B7)*(Experiments!E$2:E$64=1))} -> 2 | F7: {=SUMPRODUCT(('Overview of indicators and DLS'!$C$4:$C$66=$B7)*(Experiments!F$2:F$64=1))} -> 2 | G7: {=SUMPRODUCT(('Overview of indicators and DLS'!$C$4:$C$66=$B7)*(Experiments!G$2:G$64=1))} -> 4 | H7: {=SUMPRODUCT(('Overview of indicators and DLS'!$C$4:$C$66=$B7)*(Experiments!H$2:H$64=1))} -> 1 | I7: {=SUMPRODUCT(('Overview of indicators and DLS'!$C$4:$C$66=$B7)*(Experiments!J$2:J$64=1))} -> 0 | J7: {=SUMPRODUCT(('Overview of indicators and DLS'!$C$4:$C$66=$B7)*(Experiments!K$2:K$64=1))} -> 0 | K7: {=SUMPRODUCT(('Overview of indicators and DLS'!$C$4:$C$66=$B7)*(Experiments!L$2:L$64=1))} -> 0 | L7: {=SUMPRODUCT(('Overview of indicators and DLS'!$C$4:$C$66=$B7)*(Experiments!M$2:M$64=1))} -> 0 | M7: {=SUMPRODUCT(('Overview of indicators and DLS'!$C$4:$C$66=$B7)*(Experiments!N$2:N$64=1))} -> 0 | N7: {=SUMPRODUCT(('Overview of indicators and DLS'!$C$4:$C$66=$B7)*(Experiments!O$2:O$64=1))} -> 0 | O7: {=SUMPRODUCT(('Overview of indicators and DLS'!$C$4:$C$66=$B7)*(Experiments!P$2:P$64=1))} -> 0
B8: Sanitation | C8: {=SUMPRODUCT(('Overview of indicators and DLS'!$C$4:$C$66=$B8)*(Experiments!C$2:C$64=1))} -> 1 | D8: {=SUMPRODUCT(('Overview of indicators and DLS'!$C$4:$C$66=$B8)*(Experiments!D$2:D$64=1))} -> 2 | E8: {=SUMPRODUCT(('Overview of indicators and DLS'!$C$4:$C$66=$B8)*(Experiments!E$2:E$64=1))} -> 1 | F8: {=SUMPRODUCT(('Overview of indicators and DLS'!$C$4:$C$66=$B8)*(Experiments!F$2:F$64=1))} -> 1 | G8: {=SUMPRODUCT(('Overview of indicators and DLS'!$C$4:$C$66=$B8)*(Experiments!G$2:G$64=1))} -> 2 | H8: {=SUMPRODUCT(('Overview of indicators and DLS'!$C$4:$C$66=$B8)*(Experiments!H$2:H$64=1))} -> 1 | I8: {=SUMPRODUCT(('Overview of indicators and DLS'!$C$4:$C$66=$B8)*(Experiments!J$2:J$64=1))} -> 0 | J8: {=SUMPRODUCT(('Overview of indicators and DLS'!$C$4:$C$66=$B8)*(Experiments!K$2:K$64=1))} -> 0 | K8: {=SUMPRODUCT(('Overview of indicators and DLS'!$C$4:$C$66=$B8)*(Experiments!L$2:L$64=1))} -> 0 | L8: {=SUMPRODUCT(('Overview of indicators and DLS'!$C$4:$C$66=$B8)*(Experiments!M$2:M$64=1))} -> 0 | M8: {=SUMPRODUCT(('Overview of indicators and DLS'!$C$4:$C$66=$B8)*(Experiments!N$2:N$64=1))} -> 0 | N8: {=SUMPRODUCT(('Overview of indicators and DLS'!$C$4:$C$66=$B8)*(Experiments!O$2:O$64=1))} -> 0 | O8: {=SUMPRODUCT(('Overview of indicators and DLS'!$C$4:$C$66=$B8)*(Experiments!P$2:P$64=1))} -> 0
B9: Food preparation | C9: {=SUMPRODUCT(('Overview of indicators and DLS'!$C$4:$C$66=$B9)*(Experiments!C$2:C$64=1))} -> 2 | D9: {=SUMPRODUCT(('Overview of indicators and DLS'!$C$4:$C$66=$B9)*(Experiments!D$2:D$64=1))} -> 3 | E9: {=SUMPRODUCT(('Overview of indicators and DLS'!$C$4:$C$66=$B9)*(Experiments!E$2:E$64=1))} -> 1 | F9: {=SUMPRODUCT(('Overview of indicators and DLS'!$C$4:$C$66=$B9)*(Experiments!F$2:F$64=1))} -> 1 | G9: {=SUMPRODUCT(('Overview of indicators and DLS'!$C$4:$C$66=$B9)*(Experiments!G$2:G$64=1))} -> 3 | H9: {=SUMPRODUCT(('Overview of indicators and DLS'!$C$4:$C$66=$B9)*(Experiments!H$2:H$64=1))} -> 1 | I9: {=SUMPRODUCT(('Overview of indicators and DLS'!$C$4:$C$66=$B9)*(Experiments!J$2:J$64=1))} -> 0 | J9: {=SUMPRODUCT(('Overview of indicators and DLS'!$C$4:$C$66=$B9)*(Experiments!K$2:K$64=1))} -> 0 | K9: {=SUMPRODUCT(('Overview of indicators and DLS'!$C$4:$C$66=$B9)*(Experiments!L$2:L$64=1))} -> 0 | L9: {=SUMPRODUCT(('Overview of indicators and DLS'!$C$4:$C$66=$B9)*(Experiments!M$2:M$64=1))} -> 0 | M9: {=SUMPRODUCT(('Overview of indicators and DLS'!$C$4:$C$66=$B9)*(Experiments!N$2:N$64=1))} -> 0 | N9: {=SUMPRODUCT(('Overview of indicators and DLS'!$C$4:$C$66=$B9)*(Experiments!O$2:O$64=1))} -> 0 | O9: {=SUMPRODUCT(('Overview of indicators and DLS'!$C$4:$C$66=$B9)*(Experiments!P$2:P$64=1))} -> 0
B10: Thermal comfort | C10: {=SUMPRODUCT(('Overview of indicators and DLS'!$C$4:$C$66=$B10)*(Experiments!C$2:C$64=1))} -> 1 | D10: {=SUMPRODUCT(('Overview of indicators and DLS'!$C$4:$C$66=$B10)*(Experiments!D$2:D$64=1))} -> 1 | E10: {=SUMPRODUCT(('Overview of indicators and DLS'!$C$4:$C$66=$B10)*(Experiments!E$2:E$64=1))} -> 1 | F10: {=SUMPRODUCT(('Overview of indicators and DLS'!$C$4:$C$66=$B10)*(Experiments!F$2:F$64=1))} -> 1 | G10: {=SUMPRODUCT(('Overview of indicators and DLS'!$C$4:$C$66=$B10)*(Experiments!G$2:G$64=1))} -> 1 | H10: {=SUMPRODUCT(('Overview of indicators and DLS'!$C$4:$C$66=$B10)*(Experiments!H$2:H$64=1))} -> 1 | I10: {=SUMPRODUCT(('Overview of indicators and DLS'!$C$4:$C$66=$B10)*(Experiments!J$2:J$64=1))} -> 0 | J10: {=SUMPRODUCT(('Overview of indicators and DLS'!$C$4:$C$66=$B10)*(Experiments!K$2:K$64=1))} -> 0 | K10: {=SUMPRODUCT(('Overview of indicators and DLS'!$C$4:$C$66=$B10)*(Experiments!L$2:L$64=1))} -> 0 | L10: {=SUMPRODUCT(('Overview of indicators and DLS'!$C$4:$C$66=$B10)*(Experiments!M$2:M$64=1))} -> 0 | M10: {=SUMPRODUCT(('Overview of indicators and DLS'!$C$4:$C$66=$B10)*(Experiments!N$2:N$64=1))} -> 0 | N10: {=SUMPRODUCT(('Overview of indicators and DLS'!$C$4:$C$66=$B10)*(Experiments!O$2:O$64=1))} -> 0 | O10: {=SUMPRODUCT(('Overview of indicators and DLS'!$C$4:$C$66=$B10)*(Experiments!P$2:P$64=1))} -> 0
B11: Non material / Non-DLS | C11: {=SUMPRODUCT(('Overview of indicators and DLS'!$C$4:$C$66=$B11)*(Experiments!C$2:C$64=1))} -> 9 | D11: {=SUMPRODUCT(('Overview of indicators and DLS'!$C$4:$C$66=$B11)*(Experiments!D$2:D$64=1))} -> 10 | E11: {=SUMPRODUCT(('Overview of indicators and DLS'!$C$4:$C$66=$B11)*(Experiments!E$2:E$64=1))} -> 0 | F11: {=SUMPRODUCT(('Overview of indicators and DLS'!$C$4:$C$66=$B11)*(Experiments!F$2:F$64=1))} -> 0 | G11: {=SUMPRODUCT(('Overview of indicators and DLS'!$C$4:$C$66=$B11)*(Experiments!G$2:G$64=1))} -> 0 | H11: {=SUMPRODUCT(('Overview of indicators and DLS'!$C$4:$C$66=$B11)*(Experiments!H$2:H$64=1))} -> 2 | I11: {=SUMPRODUCT(('Overview of indicators and DLS'!$C$4:$C$66=$B11)*(Experiments!J$2:J$64=1))} -> 0 | J11: {=SUMPRODUCT(('Overview of indicators and DLS'!$C$4:$C$66=$B11)*(Experiments!K$2:K$64=1))} -> 0 | K11: {=SUMPRODUCT(('Overview of indicators and DLS'!$C$4:$C$66=$B11)*(Experiments!L$2:L$64=1))} -> 0 | L11: {=SUMPRODUCT(('Overview of indicators and DLS'!$C$4:$C$66=$B11)*(Experiments!M$2:M$64=1))} -> 0 | M11: {=SUMPRODUCT(('Overview of indicators and DLS'!$C$4:$C$66=$B11)*(Experiments!N$2:N$64=1))} -> 0 | N11: {=SUMPRODUCT(('Overview of indicators and DLS'!$C$4:$C$66=$B11)*(Experiments!O$2:O$64=1))} -> 0 | O11: {=SUMPRODUCT(('Overview of indicators and DLS'!$C$4:$C$66=$B11)*(Experiments!P$2:P$64=1))} -> 0
B12: Education | C12: {=SUMPRODUCT(('Overview of indicators and DLS'!$C$4:$C$66=$B12)*(Experiments!C$2:C$64=1))} -> 4 | D12: {=SUMPRODUCT(('Overview of indicators and DLS'!$C$4:$C$66=$B12)*(Experiments!D$2:D$64=1))} -> 5 | E12: {=SUMPRODUCT(('Overview of indicators and DLS'!$C$4:$C$66=$B12)*(Experiments!E$2:E$64=1))} -> 1 | F12: {=SUMPRODUCT(('Overview of indicators and DLS'!$C$4:$C$66=$B12)*(Experiments!F$2:F$64=1))} -> 1 | G12: {=SUMPRODUCT(('Overview of indicators and DLS'!$C$4:$C$66=$B12)*(Experiments!G$2:G$64=1))} -> 9 | H12: {=SUMPRODUCT(('Overview of indicators and DLS'!$C$4:$C$66=$B12)*(Experiments!H$2:H$64=1))} -> 3 | I12: {=SUMPRODUCT(('Overview of indicators and DLS'!$C$4:$C$66=$B12)*(Experiments!J$2:J$64=1))} -> 0 | J12: {=SUMPRODUCT(('Overview of indicators and DLS'!$C$4:$C$66=$B12)*(Experiments!K$2:K$64=1))} -> 0 | K12: {=SUMPRODUCT(('Overview of indicators and DLS'!$C$4:$C$66=$B12)*(Experiments!L$2:L$64=1))} -> 0 | L12: {=SUMPRODUCT(('Overview of indicators and DLS'!$C$4:$C$66=$B12)*(Experiments!M$2:M$64=1))} -> 0 | M12: {=SUMPRODUCT(('Overview of indicators and DLS'!$C$4:$C$66=$B12)*(Experiments!N$2:N$64=1))} -> 0 | N12: {=SUMPRODUCT(('Overview of indicators and DLS'!$C$4:$C$66=$B12)*(Experiments!O$2:O$64=1))} -> 0 | O12: {=SUMPRODUCT(('Overview of indicators and DLS'!$C$4:$C$66=$B12)*(Experiments!P$2:P$64=1))} -> 0
B13: Social connectedness | C13: {=SUMPRODUCT(('Overview of indicators and DLS'!$C$4:$C$66=$B13)*(Experiments!C$2:C$64=1))} -> 3 | D13: {=SUMPRODUCT(('Overview of indicators and DLS'!$C$4:$C$66=$B13)*(Experiments!D$2:D$64=1))} -> 3 | E13: {=SUMPRODUCT(('Overview of indicators and DLS'!$C$4:$C$66=$B13)*(Experiments!E$2:E$64=1))} -> 2 | F13: {=SUMPRODUCT(('Overview of indicators and DLS'!$C$4:$C$66=$B13)*(Experiments!F$2:F$64=1))} -> 2 | G13: {=SUMPRODUCT(('Overview of indicators and DLS'!$C$4:$C$66=$B13)*(Experiments!G$2:G$64=1))} -> 3 | H13: {=SUMPRODUCT(('Overview of indicators and DLS'!$C$4:$C$66=$B13)*(Experiments!H$2:H$64=1))} -> 2 | I13: {=SUMPRODUCT(('Overview of indicators and DLS'!$C$4:$C$66=$B13)*(Experiments!J$2:J$64=1))} -> 0 | J13: {=SUMPRODUCT(('Overview of indicators and DLS'!$C$4:$C$66=$B13)*(Experiments!K$2:K$64=1))} -> 0 | K13: {=SUMPRODUCT(('Overview of indicators and DLS'!$C$4:$C$66=$B13)*(Experiments!L$2:L$64=1))} -> 0 | L13: {=SUMPRODUCT(('Overview of indicators and DLS'!$C$4:$C$66=$B13)*(Experiments!M$2:M$64=1))} -> 0 | M13: {=SUMPRODUCT(('Overview of indicators and DLS'!$C$4:$C$66=$B13)*(Experiments!N$2:N$64=1))} -> 0 | N13: {=SUMPRODUCT(('Overview of indicators and DLS'!$C$4:$C$66=$B13)*(Experiments!O$2:O$64=1))} -> 0 | O13: {=SUMPRODUCT(('Overview of indicators and DLS'!$C$4:$C$66=$B13)*(Experiments!P$2:P$64=1))} -> 0
B14: Housing | C14: {=SUMPRODUCT(('Overview of indicators and DLS'!$C$4:$C$66=$B14)*(Experiments!C$2:C$64=1))} -> 0 | D14: {=SUMPRODUCT(('Overview of indicators and DLS'!$C$4:$C$66=$B14)*(Experiments!D$2:D$64=1))} -> 1 | E14: {=SUMPRODUCT(('Overview of indicators and DLS'!$C$4:$C$66=$B14)*(Experiments!E$2:E$64=1))} -> 1 | F14: {=SUMPRODUCT(('Overview of indicators and DLS'!$C$4:$C$66=$B14)*(Experiments!F$2:F$64=1))} -> 1 | G14: {=SUMPRODUCT(('Overview of indicators and DLS'!$C$4:$C$66=$B14)*(Experiments!G$2:G$64=1))} -> 1 | H14: {=SUMPRODUCT(('Overview of indicators and DLS'!$C$4:$C$66=$B14)*(Experiments!H$2:H$64=1))} -> 1 | I14: {=SUMPRODUCT(('Overview of indicators and DLS'!$C$4:$C$66=$B14)*(Experiments!J$2:J$64=1))} -> 0 | J14: {=SUMPRODUCT(('Overview of indicators and DLS'!$C$4:$C$66=$B14)*(Experiments!K$2:K$64=1))} -> 0 | K14: {=SUMPRODUCT(('Overview of indicators and DLS'!$C$4:$C$66=$B14)*(Experiments!L$2:L$64=1))} -> 0 | L14: {=SUMPRODUCT(('Overview of indicators and DLS'!$C$4:$C$66=$B14)*(Experiments!M$2:M$64=1))} -> 0 | M14: {=SUMPRODUCT(('Overview of indicators and DLS'!$C$4:$C$66=$B14)*(Experiments!N$2:N$64=1))} -> 0 | N14: {=SUMPRODUCT(('Overview of indicators and DLS'!$C$4:$C$66=$B14)*(Experiments!O$2:O$64=1))} -> 0 | O14: {=SUMPRODUCT(('Overview of indicators and DLS'!$C$4:$C$66=$B14)*(Experiments!P$2:P$64=1))} -> 0
B15: Physical Connectedness | C15: {=SUMPRODUCT(('Overview of indicators and DLS'!$C$4:$C$66=$B15)*(Experiments!C$2:C$64=1))} -> 0 | D15: {=SUMPRODUCT(('Overview of indicators and DLS'!$C$4:$C$66=$B15)*(Experiments!D$2:D$64=1))} -> 0 | E15: {=SUMPRODUCT(('Overview of indicators and DLS'!$C$4:$C$66=$B15)*(Experiments!E$2:E$64=1))} -> 0 | F15: {=SUMPRODUCT(('Overview of indicators and DLS'!$C$4:$C$66=$B15)*(Experiments!F$2:F$64=1))} -> 0 | G15: {=SUMPRODUCT(('Overview of indicators and DLS'!$C$4:$C$66=$B15)*(Experiments!G$2:G$64=1))} -> 0 | H15: {=SUMPRODUCT(('Overview of indicators and DLS'!$C$4:$C$66=$B15)*(Experiments!H$2:H$64=1))} -> 0 | I15: {=SUMPRODUCT(('Overview of indicators and DLS'!$C$4:$C$66=$B15)*(Experiments!J$2:J$64=1))} -> 0 | J15: {=SUMPRODUCT(('Overview of indicators and DLS'!$C$4:$C$66=$B15)*(Experiments!K$2:K$64=1))} -> 0 | K15: {=SUMPRODUCT(('Overview of indicators and DLS'!$C$4:$C$66=$B15)*(Experiments!L$2:L$64=1))} -> 0 | L15: {=SUMPRODUCT(('Overview of indicators and DLS'!$C$4:$C$66=$B15)*(Experiments!M$2:M$64=1))} -> 0 | M15: {=SUMPRODUCT(('Overview of indicators and DLS'!$C$4:$C$66=$B15)*(Experiments!N$2:N$64=1))} -> 0 | N15: {=SUMPRODUCT(('Overview of indicators and DLS'!$C$4:$C$66=$B15)*(Experiments!O$2:O$64=1))} -> 0 | O15: {=SUMPRODUCT(('Overview of indicators and DLS'!$C$4:$C$66=$B15)*(Experiments!P$2:P$64=1))} -> 0 | Q15: Physical connectedness (mobility) is not well represented globally through time
B17: Number of indicators | C17: =SUM(C5:C15) -> 33 | D17: =SUM(D5:D15) -> 44 | E17: =SUM(E5:E15) -> 11 | F17: =SUM(F5:F15) -> 11 | G17: =SUM(G5:G15) -> 38 | H17: =SUM(H5:H15) -> 15 | I17: =SUM(I5:I15) -> 0 | J17: =SUM(J5:J15) -> 0 | ... O17: =SUM(O5:O15) -> 0
B18: Of which SPI | C18: =SUM(Experiments!C2:C53) -> 33 | D18: =SUM(Experiments!D2:D53) -> 33 | E18: =SUM(Experiments!E2:E53) -> 7 | F18: =SUM(Experiments!F2:F53) -> 10 | G18: =SUM(Experiments!G2:G53) -> 28 | H18: =SUM(Experiments!H2:H53) -> 11 | I18: =SUM(Experiments!J2:J53) -> 0 | J18: =SUM(Experiments!K2:K53) -> 0 | K18: =SUM(Experiments!L2:L53) -> 0 | L18: =SUM(Experiments!M2:M53) -> 0 | M18: =SUM(Experiments!N2:N53) -> 0 | N18: =SUM(Experiments!O2:O53) -> 0 | O18: =SUM(Experiments!P2:P53) -> 0
B19: Of which Extended | C19: =SUM(Experiments!C54:C64) -> 0 | D19: =SUM(Experiments!D54:D64) -> 11 | E19: =SUM(Experiments!E54:E64) -> 4 | F19: =SUM(Experiments!F54:F64) -> 1 | G19: =SUM(Experiments!G54:G64) -> 10 | H19: =SUM(Experiments!H54:H64) -> 4 | I19: =SUM(Experiments!J54:J64) -> 0 | J19: =SUM(Experiments!K54:K64) -> 0 | K19: =SUM(Experiments!L54:L64) -> 0 | L19: =SUM(Experiments!M54:M64) -> 0 | M19: =SUM(Experiments!N54:N64) -> 0 | N19: =SUM(Experiments!O54:O64) -> 0 | O19: =SUM(Experiments!P54:P64) -> 0
B21: Thoughts | C21: Before run | I21: After run
B22: {=TRANSPOSE(_xlfn.ANCHORARRAY(C4))} -> BHN_FWB | C22: Only BHN and FWB from SPI to cluster the countries. Low amount of missingness high stability of clusters is expected between imputed sets. Housing dimension is lacking
B23: BHN_FWB_AllExt | C23: Only BHN, FWB and all extended variables to cluster the countries. Higher amount of missingness may cause unstable clusters. All possible DLS dimensions are covered.
B24: Few_indicators_closest_DLS_coverage | C24: Choosing as few indicators as possible to cover DLS dimensions. Indicators are chosen so that they align most with the indicators presented in the subnational study. Redundancy is avoided. High missingness may cause problems
B25: Few indicators_SPI_preferred | C25: Choosing as few indicators as possible to cover DLS dimensions. Indicators are chosen from SPI if possiblle to avoid missing data porblems. Redundancy is avoided.
B26: No_non_DLS | C26: Clustering where all variables that are not directly related to DLS dimensions are excluded, but all others are included
B27: Only_%_of_pop | C27: Clustering that only includes indicators that describes attainment as a proportion of population. This will provide clusters where we can easily determine national DLS coverage afterwards.
B28: Add new here
B29: 0
B30: 0
B31: 0
B32: 0
B33: 0
B34: 0
B35: 0

Sheet Experiments
A1: Available Indicator (1 indicates that the indicator is included) | B1: Related DLS dimension | C1: BHN_FWB | D1: BHN_FWB_AllExt | E1: Few_indicators_closest_DLS_coverage | F1: Few indicators_SPI_preferred | G1: No_non_DLS | H1: Only_%_of_pop | I1: Add new here
A2: {=TRANSPOSE('[1]1990-2020 Time-series data'!$Y$2:$BX$2)} -> Child stunting (% of pop.) | B2: Food & Nutrition | C2: 1 | D2: 1 | E2: 0 | F2: 0 | G2: 1 | H2: 1
A3: Deaths from infectious diseases (deaths/100,000) | B3: Health Care | C3: 1 | D3: 1 | E3: 0 | F3: 0 | G3: 1 | H3: 0
A4: Maternal mortality (deaths/100,000 live births) | B4: Health Care | C4: 1 | D4: 1 | E4: 0 | F4: 0 | G4: 1 | H4: 0
A5: Nutritional deficiencies (% of pop.) | B5: Food & Nutrition | C5: 1 | D5: 1 | E5: 1 | F5: 1 | G5: 1 | H5: 1
A6: Diet low in fruits and vegetables (0=low risk; 100=high risk) | B6: Food & Nutrition | C6: 1 | D6: 1 | E6: 0 | F6: 0 | G6: 1 | H6: 0
A7: Child mortality (deaths/1,000 live births) | B7: Health Care | C7: 1 | D7: 1 | E7: 0 | F7: 0 | G7: 1 | H7: 0
A8: No access to a handwashing facility (0=low risk; 100=high risk) | B8: Water | C8: 1 | D8: 1 | E8: 1 | F8: 1 | G8: 1 | H8: 0
A9: Deaths from unsafe water, sanitation and hygiene (deaths/100,000) | B9: Water | C9: 1 | D9: 1 | E9: 0 | F9: 0 | G9: 1 | H9: 0
A10: Improved sanitation (proportion of pop.) | B10: Sanitation | C10: 1 | D10: 1 | E10: 0 | F10: 1 | G10: 1 | H10: 0
A11: Improved water source (proportion of pop.) | B11: Water | C11: 1 | D11: 1 | E11: 0 | F11: 1 | G11: 1 | H11: 0
A12: Deaths from household air pollution (deaths/100,000) | B12: Food preparation | C12: 1 | D12: 1 | E12: 0 | F12: 0 | G12: 1 | H12: 0
A13: Prevalence of cooking with coal/biomass (proportion of pop.) | B13: Food preparation | C13: 1 | D13: 1 | E13: 1 | F13: 1 | G13: 1 | H13: 1
A14: Access to electricity (% of pop.) | B14: Thermal comfort | C14: 1 | D14: 1 | E14: 1 | F14: 1 | G14: 1 | H14: 1
... A64: Intentional homicide victims | B64: Non material / Non-DLS | C64: 0 | D64: 1 | E64: 0 | F64: 0 | G64: 0 | H64: 0
B65: Physical Connectedness

Sheet Overview of indicators and DLS
A3: SPI | B3: Available indicators | C3: Related DLS dimension
A4: BHN | B4: {=TRANSPOSE('[1]1990-2020 Time-series data'!$Y$2:$BX$2)} -> Child stunting (% of pop.) | C4: Food & Nutrition
B5: Deaths from infectious diseases (deaths/100,000) | C5: Health Care
B6: Maternal mortality (deaths/100,000 live births) | C6: Health Care
B7: Nutritional deficiencies (% of pop.) | C7: Food & Nutrition
B8: Diet low in fruits and vegetables (0=low risk; 100=high risk) | C8: Food & Nutrition
B9: Child mortality (deaths/1,000 live births) | C9: Health Care
B10: No access to a handwashing facility (0=low risk; 100=high risk) | C10: Water
B11: Deaths from unsafe water, sanitation and hygiene (deaths/100,000) | C11: Water
B12: Improved sanitation (proportion of pop.) | C12: Sanitation
B13: Improved water source (proportion of pop.) | C13: Water
A14: FWB | B14: Deaths from household air pollution (deaths/100,000) | C14: Food preparation
B15: Prevalence of cooking with coal/biomass (proportion of pop.) | C15: Food preparation
B16: Access to electricity (% of pop.) | C16: Thermal comfort
B17: Deaths from road injuries (deaths/100,000) | C17: Non material / Non-DLS
B18: Political violence (0=no violence; 4=violence often) | C18: Non material / Non-DLS
B19: Political killings and torture (0=low freedom; 1=high freedom) | C19: Non material / Non-DLS
B20: Intimate partner violence against women (% of women aged 15+) | C20: Non material / Non-DLS
B21: Interpersonal violence (deaths/100,000) | C21: Non material / Non-DLS
B22: Population with no education (proportion of pop.) | C22: Education
B23: Gender parity in basic education (distance from parity) | C23: Education
B24: Equal access to quality education (0=unequal; 4=equal) | C24: Education
B25: Mean years of schooling (years) | C25: Education
B26: Alternative sources of information (0=low; 1=high) | C26: Social connectedness
... B36: Species protection (0=low; 100=high) | C36: Non material / Non-DLS
A37: OPP | B37: Freedom of religion (0=no freedom; 4=full freedom) | C37: Non material / Non-DLS
B38: Property rights for women (0=no rights; 5=full rights) | C38: Non material / Non-DLS
B39: Freedom of assembly (0=no freedom; 4=full freedom) | C39: Non material / Non-DLS
B40: Access to justice (0=nonexistent; 1=observed) | C40: Non material / Non-DLS
B41: Freedom of discussion (0=low; 1=high) | C41: Non material / Non-DLS
B42: Political rights (1=full rights; 7=no rights) | C42: Non material / Non-DLS
B43: Public sector corruption (0=low corruption; 1=high corruption) | C43: Non material / Non-DLS
B44: Freedom of domestic movement (0=low; 1=high) | C44: Non material / Non-DLS
B45: Satisfied demand for contraception (% satisfied demand) | C45: Non material / Non-DLS
B46: Early marriage (% of married women aged 15-19) | C46: Non material / Non-DLS
B47: Vulnerable employment (% of total employment) | C47: Non material / Non-DLS
B48: Equal protection of social groups (0=low; 1=high) | C48: Non material / Non-DLS
B49: Equal access to power (0=low; 1=high) | C49: Non material / Non-DLS
... B55: Years of tertiary schooling (years) | C55: Education
A56: Extra sources | B56: Primary School Enrollment (% of pop in school age) | C56: Education
...
